Workbook

Sheet Start Here
A1: LLMs from First Principles — the roadmap
A2: 216 episodes · 18 modules · 9 flagship projects · 2026-10-16 → 2027-05-18
A4: How to use this sheet
A5: 1. Today tab: what to record today (auto-filters the Calendar by today's date).
A6: 2. Night before: open Episodes & Scripts, read tomorrow's two rows (hook + beats). The full prep sheet is in the repo at the 'Prep sheet' path.
A7: 3. Record in Meld (TALK/CODE scenes). Then tick Recorded on the Calendar row; Claude runs the HyperFrames edit + Short + explainer.
A8: 4. Review renders, upload, tick each platform column. Sunday: fill the Scorecard.
A9: 5. Flagship projects (Projects tab) are the resume. Episodes are the path to them. On sprint days, slot B is a filmed project build log.
A11: The rule of the series
A12: Every episode builds or measures something real and ends with a RECEIPT: allclose against the production implementation, a gradcheck, a benchmark vs the hardware peak, or a published number.
A14: Repo: ~/Documents/DL-content · CLI: dl today | dl start | dl prep | dl explainer | dl done · Sources of truth: curriculum.json (content), this sheet (daily status)
A16: Milestones
... A30: • After P4 + P6 + P7 (~2027-05-18): post-training / RL / safety research-engineer roles at every frontier lab.

Sheet Today
A1: Today | B1: =TODAY()
A3: Recording today
A4: =IFERROR(FILTER(Calendar!B2:E500, Calendar!A2:A500=TODAY()), "Nothing scheduled today")
A8: Tomorrow (read the prep sheets tonight)
A9: =IFERROR(FILTER(Calendar!B2:E500, Calendar!A2:A500=TODAY()+1), "Nothing scheduled")
A13: Scripts for today
A14: =IFERROR(FILTER({'Episodes & Scripts'!B2:B300, 'Episodes & Scripts'!F2:F300, 'Episodes & Scripts'!G2:G300}, 'Episodes & Scripts'!D2:D300=TODAY()), "")
A20: Progress
A21: Episodes recorded | B21: =COUNTIF('Episodes & Scripts'!P2:P300,"Y")
A22: Episodes published (YouTube) | B22: =COUNTIF('Episodes & Scripts'!R2:R300,"Y")
A23: Total episodes | B23: 216
A24: Behind / ahead (episodes) | B24: =B21-COUNTIFS('Episodes & Scripts'!D2:D300,"<"&TODAY())

Sheet Roadmap
A1: Phase | B1: Module | C1: Name | D1: Eps | E1: Start | F1: End | G1: Hardware | H1: Feeds project | I1: Resume line it earns (fill X/Y with real numbers) | J1: Primary sources
A2: 1 Foundations | B2: M00 | C2: Start Here | D2: 2 | E2: 2026-10-16 | F2: 2026-10-24 | G2: Mac | J2: Stanford CS336: Language Modeling from Scratch Karpathy: Neural Networks, Zero to Hero PyTorch: Learn the Basics RunPod docs
A3: 1 Foundations | B3: M01 | C3: PyTorch from Zero | D3: 14 | E3: 2026-10-16 | F3: 2026-10-24 | G3: Mac (MPS) | I3: Fluent PyTorch: tensors, autograd, nn.Module, training loops (14-part series + 1-hour cut) | J3: PyTorch: Learn the Basics PyTorch documentation einops Karpathy: Neural Networks, Zero to Hero
A4: 1 Foundations | B4: M02 | C4: The Math You Actually Need | D4: 10 | E4: 2026-10-26 | F4: 2026-10-30 | G4: Mac | I4: Derived backprop, softmax/cross-entropy gradients and init variance by hand, verified against autograd | J4: Mathematics for Machine Learning (Deisenroth et al.) 3Blue1Brown: Neural networks series Dive into Deep Learning (d2l.ai) Stanford CS336: Language Modeling from Scratch Karpathy: Neural Networks, Zero to Hero He et al. 2015, Delving Deep into Rectifiers (Kaiming init)
A5: 1 Foundations | B5: M03 | C5: Neural Nets from Scratch | D5: 10 | E5: 2026-10-31 | F5: 2026-11-05 | G5: Mac | I5: Built an autograd engine and character-level LMs from scratch (micrograd/makemore lineage) | J5: karpathy/micrograd Karpathy: Neural Networks, Zero to Hero karpathy/makemore Bengio et al. 2003, A Neural Probabilistic Language Model Ioffe & Szegedy 2015, Batch Normalization Ba et al. 2016, Layer Normalization
A6: 2 Build the LLM | B6: M04 | C6: Tokenization | D6: 8 | E6: 2026-11-06 | F6: 2026-11-10 | G6: Mac | I6: Implemented a byte-level BPE tokenizer from scratch; N MB/s on TinyStories | J6: Karpathy: Let's build the GPT Tokenizer Stanford CS336: Language Modeling from Scratch Sennrich et al. 2015, Subword units (BPE) karpathy/minbpe openai/tiktoken google/sentencepiece
A7: 2 Build the LLM | B7: M05 | C7: The Transformer, Layer by Layer | D7: 18 | E7: 2026-11-11 | F7: 2026-11-20 | G7: Mac | I7: Implemented GPT from scratch (RoPE, RMSNorm, SwiGLU, GQA) and verified it loads GPT-2 weights | J7: Karpathy: Let's build GPT from scratch Jay Alammar: The Illustrated Transformer Anthropic: Transformer Circuits thread Vaswani et al. 2017, Attention Is All You Need Harvard NLP: The Annotated Transformer 3Blue1Brown: Neural networks series
A8: 2 Build the LLM | B8: M06 | C8: Training an LLM | D8: 16 | E8: 2026-11-21 | F8: 2026-11-30 | G8: Mac + RunPod 8xH100 (15 min) | H8: P5 | I8: Trained a GPT on TinyStories (val loss X); fit a scaling law; ran the NanoGPT speedrun on 8xH100 | J8: Stanford CS336: Language Modeling from Scratch karpathy/nanoGPT Kingma & Ba 2014, Adam Loshchilov & Hutter 2017, Decoupled Weight Decay (AdamW) Micikevicius et al. 2017, Mixed Precision Training Eldan & Li 2023, TinyStories
A9: 3 Systems | B9: M07 | C9: GPUs, CUDA and Triton | D9: 18 | E9: 2026-12-01 | F9: 2026-12-17 | G9: RunPod 1x RTX 4090 | H9: P1, P8, P9 | I9: Wrote CUDA and Triton kernels (tiled matmul, softmax, RMSNorm) benchmarked against cuBLAS/PyTorch | J9: Modal: GPU Glossary Hwu, Kirk, El Hajj: Programming Massively Parallel Processors, 5e Horace He: Making Deep Learning Go Brrrr Google DeepMind: How to Scale Your Model PyTorch: Profiler recipe NVIDIA CUDA C++ Programming Guide
A10: 3 Systems | B10: M08 | C10: FlashAttention | D10: 8 | E10: 2026-12-18 | F10: 2026-12-23 | G10: RunPod 1x RTX 4090 | H10: P1 | I10: Implemented FlashAttention forward+backward in Triton; X% of SDPA throughput | J10: Dao et al. 2022, FlashAttention Horace He: Making Deep Learning Go Brrrr Milakov & Gimelshein 2018, Online normalizer for softmax Umar Jamil (YouTube) Triton tutorials Dao 2023, FlashAttention-2
A11: 3 Systems | B11: M09 | C11: Modern Architectures | D11: 10 | E11: 2026-12-24 | F11: 2027-01-04 | G11: Mac + RunPod | H11: P5, P6 | I11: Implemented MLA, MoE routing and YaRN context extension from the DeepSeek/Llama papers | J11: DeepSeek-V3 Technical Report Ainslie et al. 2023, GQA Peng et al. 2023, YaRN hkproj/torchfeather (distributed training from first principles) DeepSeek-V2 (Multi-head Latent Attention) Fedus et al. 2021, Switch Transformers
A12: 3 Systems | B12: M10 | C12: Distributed Training | D12: 16 | E12: 2027-01-05 | F12: 2027-01-14 | G12: Mac (gloo) + RunPod 4x GPU | H12: P3, P6 | I12: Built DP, FSDP, TP, PP, CP and EP from scratch (torchfeather); measured scaling on 4 GPUs | J12: Hugging Face: The Ultra-Scale Playbook Google DeepMind: How to Scale Your Model hkproj/torchfeather (distributed training from first principles) PyTorch: Distributed overview Rajbhandari et al. 2019, ZeRO PyTorch: FSDP tutorial
A13: 4 Post-training + serving | B13: M11 | C13: Post-Training: SFT, LoRA, RLHF, DPO, GRPO | D13: 16 | E13: 2027-01-15 | F13: 2027-02-02 | G13: RunPod 1x A100/H100 | H13: P4 | I13: Implemented SFT, LoRA, DPO and GRPO from scratch; GRPO lifted GSM8K accuracy from X to Y | J13: Ouyang et al. 2022, InstructGPT Nathan Lambert: The RLHF Book Hugging Face TRL docs Stanford CS336: Language Modeling from Scratch Hu et al. 2021, LoRA Dettmers et al. 2023, QLoRA
A14: 4 Post-training + serving | B14: M12 | C14: Quantization | D14: 10 | E14: 2027-02-03 | F14: 2027-02-13 | G14: RunPod 1x RTX 4090 | H14: P8 | I14: Implemented absmax/zero-point, GPTQ and AWQ; measured perplexity vs speed at 8/4 bits | J14: Micikevicius et al. 2022, FP8 Formats for Deep Learning Maarten Grootendorst: A Visual Guide to Quantization pytorch/ao (quantization + low precision) Dettmers et al. 2022, LLM.int8() Xiao et al. 2022, SmoothQuant Frantar et al. 2022, GPTQ
A15: 4 Post-training + serving | B15: M13 | C15: Inference Engines: KV Cache to SGLang | D15: 16 | E15: 2027-02-15 | F15: 2027-03-04 | G15: RunPod 1x RTX 4090 | H15: P2 | I15: Built a mini inference engine (KV cache, continuous batching, paged KV); benchmarked vs vLLM/SGLang | J15: BentoML: LLM Inference Handbook Google DeepMind: How to Scale Your Model hkproj/torchfeather (distributed training from first principles) Horace He: Making Deep Learning Go Brrrr Yu et al. 2022, Orca (continuous batching) GeeeekExplorer/nano-vllm
A16: 5 Research | B16: M14 | C16: Evals and Interpretability | D16: 10 | E16: 2027-03-05 | F16: 2027-03-16 | G16: Mac + RunPod | H16: P7 | I16: Built evals with lm-eval-harness and Inspect; activation patching, probes and SAEs with TransformerLens | J16: EleutherAI lm-evaluation-harness Stanford CS336: Language Modeling from Scratch UK AISI Inspect (eval framework) TransformerLens Anthropic: Transformer Circuits thread ARENA (alignment research engineering curriculum)
A17: 5 Research | B17: M15 | C17: The DeepSeek Playbook | D17: 16 | E17: 2027-03-17 | F17: 2027-04-03 | G17: Mac + RunPod 1-8x H100 | H17: P6 | I17: Rebuilt DeepSeek's key ideas (DeepSeekMoE, MTP, FP8 training, DSA, mHC, Engram) and ablated them against a dense baseline | J17: DeepSeek-V3 Technical Report DeepSeek LLM: scaling open-source LMs with longtermism DeepSeekMoE: fine-grained + shared experts DeepSeek-V2 (Multi-head Latent Attention) deepseek-ai/DeepGEMM Micikevicius et al. 2022, FP8 Formats for Deep Learning
A18: 5 Research | B18: M16 | C18: Research Frontier | D18: 14 | E18: 2027-04-05 | F18: 2027-04-20 | G18: RunPod | H18: P4, P7 | I18: Reproduced N recent papers with public code and write-ups; one original result published | J18: alphaXiv (discuss arXiv papers) Lilian Weng's blog Karpathy: A Recipe for Training Neural Networks John Schulman: Nuts and Bolts of Deep RL Research Keller Jordan: Muon optimizer Moonshot 2025, Muon is Scalable for LLM Training
A19: 5 Research | B19: M17 | C19: Capstones | D19: 4 | E19: 2027-04-21 | F19: 2027-04-24 | G19: RunPod | I19: End to end: pretrain, post-train, quantize and serve a small LLM, with every number published | J19: karpathy/nanochat Stanford CS336: Language Modeling from Scratch GeeeekExplorer/nano-vllm pytorch/ao (quantization + low precision) hkproj/torchfeather (distributed training from first principles) Hugging Face: The Ultra-Scale Playbook

Sheet Calendar
A1: Date | B1: Day | C1: Slot | D1: Code | E1: What | F1: Kind | G1: Done | H1: Notes
A2: 46311 | B2: Fri | C2: A | D2: M00E02 | E2: Setup: uv, PyTorch, MPS vs CUDA, RunPod in 10 minutes | F2: episode | G2: N
A3: 46311 | B3: Fri | C3: B | D3: M01E01 | E3: Tensors: what they actually are | F3: episode | G3: N
A4: 46312 | B4: Sat | C4: A | D4: M01E02 | E4: Creating tensors and dtypes | F4: episode | G4: N
A5: 46312 | B5: Sat | C5: B | D5: M01E03 | E5: Indexing, views and strides | F5: episode | G5: N
A6: 46313 | B6: Sun | E6: Weekly review, thumbnails batch, read next week's prep | F6: review
A7: 46314 | B7: Mon | C7: A | D7: M01E04 | E7: Broadcasting: the bug factory | F7: episode | G7: N
A8: 46314 | B8: Mon | C8: B | D8: M01E05 | E8: Matmul, reductions and einsum | F8: episode | G8: N
A9: 46315 | B9: Tue | C9: A | D9: M01E06 | E9: Autograd: how PyTorch computes gradients | F9: episode | G9: N
A10: 46315 | B10: Tue | C10: B | D10: M01E07 | E10: Linear regression with raw autograd | F10: episode | G10: N
A11: 46316 | B11: Wed | C11: A | D11: M01E08 | E11: nn.Module and nn.Parameter | F11: episode | G11: N
A12: 46316 | B12: Wed | C12: B | D12: M01E09 | E12: Loss functions and optimizers | F12: episode | G12: N
A13: 46317 | B13: Thu | C13: A | D13: M01E10 | E13: The training loop, done right | F13: episode | G13: N
A14: 46317 | B14: Thu | C14: B | D14: M01E11 | E14: Dataset and DataLoader | F14: episode | G14: N
A15: 46318 | B15: Fri | C15: A | D15: M01E12 | E15: MNIST MLP end to end on the M4 GPU | F15: episode | G15: N
A16: 46318 | B16: Fri | C16: B | D16: M01E13 | E16: Saving, loading and reproducibility | F16: episode | G16: N
A17: 46319 | B17: Sat | C17: A | D17: M01E14 | E17: Debugging neural nets | F17: episode | G17: N
A18: 46319 | B18: Sat | C18: B | D18: M00E01 | E18: Why I'm learning LLMs by building every piece | F18: episode | G18: N
A19: 46320 | B19: Sun | E19: Weekly review, thumbnails batch, read next week's prep | F19: review
A20: 46321 | B20: Mon | C20: A | D20: M02E01 | E20: Vectors and dot products | F20: episode | G20: N
A21: 46321 | B21: Mon | C21: B | D21: M02E02 | E21: Matrix multiplication, three ways | F21: episode | G21: N
A22: 46322 | B22: Tue | C22: A | D22: M02E03 | E22: Derivatives and the chain rule | F22: episode | G22: N
A23: 46322 | B23: Tue | C23: B | D23: M02E04 | E23: Gradient descent, geometrically | F23: episode | G23: N
A24: 46323 | B24: Wed | C24: A | D24: M02E05 | E24: Backprop through a matmul by hand | F24: episode | G24: N
A25: 46323 | B25: Wed | C25: B | D25: M02E06 | E25: Probability for language models | F25: episode | G25: N
A26: 46324 | B26: Thu | C26: A | D26: M02E07 | E26: Softmax, temperature and log-sum-exp | F26: episode | G26: N
A27: 46324 | B27: Thu | C27: B | D27: M02E08 | E27: Cross-entropy is negative log-likelihood | F27: episode | G27: N
A28: 46325 | B28: Fri | C28: A | D28: M02E09 | E28: Variance and initialization | F28: episode | G28: N
A29: 46325 | B29: Fri | C29: B | D29: M02E10 | E29: Jacobians and vector-Jacobian products | F29: episode | G29: N
A30: 46326 | B30: Sat | C30: A | D30: M03E01 | E30: micrograd, part 1: an autograd engine | F30: episode | G30: N
A31: 46326 | B31: Sat | C31: B | D31: M03E02 | E31: micrograd, part 2: neurons to an MLP | F31: episode | G31: N
A32: 46327 | B32: Sun | E32: Weekly review, thumbnails batch, read next week's prep | F32: review
A33: 46328 | B33: Mon | C33: A | D33: M03E03 | E33: Bigram language model by counting | F33: episode | G33: N
A34: 46328 | B34: Mon | C34: B | D34: M03E04 | E34: The bigram model as a neural net | F34: episode | G34: N
A35: 46329 | B35: Tue | C35: A | D35: M03E05 | E35: Embeddings: lookup tables that learn | F35: episode | G35: N
A36: 46329 | B36: Tue | C36: B | D36: M03E06 | E36: Train, validation, test and overfitting | F36: episode | G36: N
A37: 46330 | B37: Wed | C37: A | D37: M03E07 | E37: Activations and dead neurons | F37: episode | G37: N
A38: 46330 | B38: Wed | C38: B | D38: M03E08 | E38: BatchNorm vs LayerNorm from scratch | F38: episode | G38: N
A39: 46331 | B39: Thu | C39: A | D39: M03E09 | E39: Residual connections | F39: episode | G39: N
A40: 46331 | B40: Thu | C40: B | D40: M03E10 | E40: Backprop by hand for a whole MLP LM | F40: episode | G40: N
...

Sheet Episodes & Scripts
A1: Ep | B1: Code | C1: Module | D1: Planned | E1: Title | F1: Hook (say first) | G1: Script beats (timed) | H1: Key math | I1: Code task | J1: Receipt (the proof) | K1: Gotchas | L1: Interview Q + answer | M1: Explainer narration (Manim) | N1: Short (vertical cut) | O1: Prep sheet ready | P1: Recorded | Q1: Edited | R1: YouTube | S1: Short posted | T1: X | U1: LinkedIn | V1: Instagram | W1: TikTok | X1: Facebook | Y1: YouTube URL | Z1: YouTube title | AA1: Thumbnail | AB1: X post | AC1: LinkedIn post | AD1: Hardware | AE1: Learn | AF1: Builds / verifies | AG1: Sources | AH1: Prep sheet path | AI1: Code file | AJ1: Explainer scene | AK1: Prereqs | AL1: Notes
A2: 1 | B2: M00E01 | C2: M00 Start Here | D2: 46319 | E2: Why I'm learning LLMs by building every piece | F2: I'm rebuilding every piece of a modern LLM by hand, and nothing counts until it matches PyTorch to the last decimal. | G2: 0:00 HOOK — I'm rebuilding every piece of a modern LLM by hand, and nothing counts until it matches PyTorch to the last decimal. 0:15 QUESTION — Using GPT or Claude is easy. Explaining why Llama 3 uses RMSNorm, or why FlashAttention is exact and still faster, is what frontier lab interviews actually test. I'm an EE and Army veteran, and the only way I trust my understanding is to build it and check it. 1:00 INTUITION — Show the map: 18 modules, 216 episodes, from tensors to an inference engine that serves Qwen3. Mac for the first 5 modules, rented GPUs after that. [EXPLAINER plays here: the curriculum as a subway map, with nine flagship projects as the stations.] 2:45 MATH — One equation, because it is the whole series in miniature. softmax(x)_i = exp(x_i) / sum_j exp(x_j). Then the identity softmax(x) = softmax(x - c) for any constant c, because exp(-c) cancels top and bottom. Remember this. It comes back in the FlashAttention module. 4:00 CODE — Repo tour on screen: curriculum/curriculum.json (every episode, its build, its sources), code/<module>/eNN_*.py (one runnable file per episode, tests at the bottom), prep/ (my notes), explainers/ (the Manim scenes). Run print_map() and read the 18 modules out loud with their hardware. 6:00 CODE — The receipt rule, live. Type softmax_naive(x, dim=-1): e = torch.exp(x); return e / e.sum(dim, keepdim=True). Type receipt(mine, ref, name) that wraps torch.testing.assert_close and prints PASS or FAIL. Test on randn(4, 8) logits: PASS. It looks done. 7:30 RECEIPT — Multiply the logits by 100 and run the same receipt. FAIL, because exp(800) is inf in float32 and inf / inf is nan. Add softmax_stable: subtract x.amax(dim, keepdim=True) first. Receipt: torch.testing.assert_close(softmax_stable(big), torch.softmax(big, -1)) passes at scales 1, 100 and 1e4. 9:00 MEASURE — Show torch.isnan(softmax_naive(big)).any() is True, and the largest safe float32 input to exp is about 88.7. A test that only uses small inputs would have shipped this bug. 10:00 TAKEAWAY — Every from-scratch piece in this series ends with a check against the production implementation. Interview line: I don't say I understand attention, I say my implementation matches SDPA within float32 tolerance, and here is the test. 10:45 NEXT — The projects: FlashAttention in Triton, an inference engine, a 4D parallel trainer, a reasoning RL reproduction. All built on this habit. Next: Setup: uv, PyTorch, MPS vs CUDA, RunPod in 10 minutes. | H2: softmax(x)_i = exp(x_i) / sum_j exp(x_j); softmax(x - c) = softmax(x) for any scalar c; stable form uses c = max_j x_j so the largest exponent is exp(0) = 1. | I2: print_map() reads curriculum/curriculum.json and prints each module code, episode count, name, hardware, and the 216 total. softmax_naive(x, dim=-1) and softmax_stable(x, dim=-1) on x of shape (4, 8). receipt(mine, ref, name) wraps torch.testing.assert_close and prints PASS/FAIL. | J2: torch.testing.assert_close(softmax_stable(x * s), torch.softmax(x * s, -1)) for s in (1, 100, 1e4) passes; softmax_naive(x * 100) fails with nan; pytest asserts 18 modules and 216 episodes. | K2: assert_close default tolerances depend on dtype (float32 is rtol 1.3e-6, atol 1e-5), so compare in the same dtype; forgetting keepdim=True in the sum broadcasts (4,) against (4, 8) and errors or silently divides the wrong axis; testing only on small random inputs hides overflow bugs. | L2: How do you know your reimplementation is correct? I test it against the reference implementation on adversarial inputs, large magnitudes, odd shapes, low precision, using assert_close with dtype-appropriate tolerances, and I gradcheck the backward in float64. | M2: Here is the whole series as one map, eighteen modules running from a single tensor to a serving engine for a real model. The first five stops run on a Mac. After the transformer module, the line switches to rented GPUs by the hour. Along the line sit nine flagship projects. Each one is unlocked by the modules right before it, like FlashAttention after the GPU module. Every station has the same rule. We build the piece from scratch, then we compare it to PyTorch's own version, number by number. Here is the rule catching a real bug. Our naive softmax matches PyTorch on small logits, so the check turns green. Scale the logits by one hundred and the exponential overflows to infinity. Infinity over infinity is not a number, and the check turns red. Subtract the max first and the biggest exponent becomes one. Same answer, no overflow, and the receipt passes at every scale. | N2: The 7:30 RECEIPT beat: naive softmax passes, multiply by 100, it returns nan, one line fixes it. Caption: 'This softmax passes every test. Until it doesn't.' | O2: Y | P2: N | Q2: N | R2: N | S2: N | T2: N | U2: N | V2: N | W2: N | X2: N | Z2: LLMs from First Principles: build every piece, check it vs PyTorch | AA2: BUILD IT. CHECK IT. | AB2: Starting a 216-episode series: rebuild every piece of a modern LLM, from tensors to an inference engine. One rule: nothing counts until it matches PyTorch. Episode 1 catches a softmax bug that passes every small test. Code + video: | AC2: I started a public series rebuilding the LLM stack from first principles: 18 modules, from tensors to serving Qwen3 with my own inference engine. The rule is that every from-scratch component must match the production implementation, checked with assert_close. In episode 1 that rule caught a naive softmax that silently returns nan once logits pass about 88. | AD2: Mac | AE2: The map: 216 videos from tensors to research, and how to follow along | AF2: Repo tour + the 'receipt' rule: every from-scratch piece is checked against PyTorch | AG2: Stanford CS336: Language Modeling from Scratch — https://cs336.stanford.edu Karpathy: Neural Networks, Zero to Hero — https://karpathy.ai/zero-to-hero.html | AH2: prep/M00-start/E01-why-i-m-learning-llms-by-building-every-piece.md | AI2: code/M00-start/e01_why_i_m_learning_llms_by_building_every_piece.py | AJ2: explainers/scenes/m00e01_why_i_m_learning_llms_by_buildin.py
A3: 2 | B3: M00E02 | C3: M00 Start Here | D3: 46311 | E3: Setup: uv, PyTorch, MPS vs CUDA, RunPod in 10 minutes | F3: Same script, my laptop GPU and a rented RTX 4090. The gap is bigger than you think, and we measure it exactly. | G3: 0:00 HOOK — Same script, my laptop GPU and a rented RTX 4090. The gap is bigger than you think, and we measure it exactly. 0:15 QUESTION — Half of ML bugs are environment bugs: the wrong torch build, a GPU you are not actually using, a timer that measures nothing. Before we touch a tensor we need one environment that works the same on an M4 Mac and on a CUDA box, and a way to rent an H100 without waking up to a surprise bill. 1:00 INTUITION — The GPU is a separate machine you send work to. Calls return before the work is done. [EXPLAINER plays here: CPU queues kernels, GPU drains them, the timer only means something after a sync.] 2:30 MATH — Matmul cost: C = A B with A (n, n) and B (n, n) has n^2 outputs, each needing n multiplies and n adds, so FLOPs = 2 n^3. At n = 4096 that is 1.37e11 FLOPs. TFLOP/s = 2 n^3 / seconds / 1e12. This one formula is how we will judge every kernel in the series. 3:30 CODE — Terminal: uv init, uv add torch pytest, uv run python -c 'import torch; print(torch.__version__, torch.backends.mps.is_available())'. Commit uv.lock so the RunPod box gets the same versions. 4:30 CODE — env_check.py: pick_device() prefers cuda, then mps, then cpu. sync(device) calls torch.cuda.synchronize() or torch.mps.synchronize(). dtype_works(dtype, device) tries an 8x8 matmul inside try/except. matmul_tflops(n, dtype, device, iters=20): randn A and B, 3 warmup matmuls, sync, time 20 matmuls, sync, return 2 n^3 / secs / 1e12. 7:00 CODE — RunPod in 3 minutes: put a small prepaid credit on the account so the balance is the hard spend cap, launch a 1x RTX 4090 pod with a PyTorch template, git clone, uv sync, uv run env_check.py. Stop the pod from the console the moment the run ends, and say out loud what an idle pod costs per hour. 8:30 RECEIPT — Speed means nothing if the answer is wrong. test_matmul_is_correct_on_device: compute a @ b in float64 on CPU as the reference, the same matmul in float32 on the device, and torch.testing.assert_close(got.double(), ref, rtol=1e-4, atol=1e-3). Passes on MPS and CUDA. Also show float64 fails on MPS in dtype_works. 9:30 MEASURE — The table: float32, bfloat16, float16 TFLOP/s at n = 4096 on M4 MPS, M4 CPU, and RTX 4090. Compare each to the vendor's quoted peak and say the percentage. Then remove the sync calls and rerun: the numbers become absurd, which proves the timer was lying. 11:00 TAKEAWAY — One lockfile, one env_check, and every benchmark synchronizes before it stops the clock. Interview line: GPU work is asynchronous, so a benchmark without a device sync measures launch overhead, not compute. 11:30 NEXT — This env_check and spend-cap habit is what lets us run the 8xH100 pretraining speedrun project later for the price of lunch. Next: Tensors: what they actually are. | H3: FLOPs(matmul n x n x n) = 2 n^3; TFLOP/s = 2 n^3 / t / 1e12; percent of peak = measured / vendor peak. | I3: env_check.py with pick_device() -> torch.device, sync(device), dtype_works(dtype, device) -> bool via an (8, 8) matmul, matmul_tflops(n=4096, dtype, device, iters=20) -> float, report() printing python/torch versions, device name, and a dtype x TFLOP/s table for float32, bfloat16, float16 plus a CPU float32 baseline at n=2048. | J3: torch.testing.assert_close((a.float().to(dev) @ b.float().to(dev)).cpu().double(), a @ b, rtol=1e-4, atol=1e-3) with a, b float64 (256, 256) on CPU; assert dtype_works(torch.bfloat16, 'mps') on macOS 14+. | K3: Timing without torch.mps.synchronize()/torch.cuda.synchronize() gives impossible TFLOP/s; float64 is not supported on MPS, so code that calls .double() on device crashes; on CUDA, float32 matmul uses full FP32 unless you call torch.set_float32_matmul_precision('high') to allow TF32, which changes your benchmark by several x; an idle RunPod pod keeps billing until it is stopped. | L3: Your benchmark says your kernel hits 2000 TFLOP/s on an H100. What went wrong? Almost certainly a missing device synchronize, so the timer measured how fast Python queued launches. Warm up, sync before and after, average many iterations, and sanity check against the hardware peak. | M3: On the left is the CPU running our Python. On the right is the GPU, a separate machine with its own memory and its own queue. When we call a matmul, the CPU drops a kernel into the GPU's queue and returns immediately, before any multiplying has happened. If we stop the timer now, we have measured how fast Python can drop boxes into a queue. The GPU has not started. A synchronize call makes the CPU wait at the door until the queue is empty. Only now does the timer measure real compute. The work itself is easy to count. Every one of the n squared outputs needs n multiplies and n adds, so two n cubed operations. Divide that count by the synced time and we get TFLOP slash s, one honest number we can compare against the chip's spec sheet. | N3: The 9:30 MEASURE beat: run the benchmark with and without synchronize, watch the fake number appear. Caption: 'Your GPU benchmark is probably lying to you.' | O3: Y | P3: N | Q3: N | R3: N | S3: N | T3: N | U3: N | V3: N | W3: N | X3: N | Z3: PyTorch setup with uv: MPS vs CUDA vs RunPod, and honest TFLOPs | AA3: YOUR BENCHMARK LIES | AB3: GPU calls are async. Time a matmul without torch.mps.synchronize() and you measure Python queueing, not compute. Built one env_check.py that runs on an M4 Mac and a rented 4090, with real TFLOP/s for fp32/bf16/fp16. Code + video: | AC3: Set up a reproducible PyTorch environment with uv that runs unchanged on an M4 Mac (MPS) and a rented RTX 4090. I wrote an env check that measures matmul TFLOP/s per dtype and verifies the device result against a float64 CPU reference. The lesson: without a device synchronize, a benchmark reports numbers the hardware physically cannot reach. | AD3: Mac | AE3: A reproducible env on a Mac and on a rented GPU, with a spend cap | AF3: env_check.py prints device, dtype support, matmul TFLOPs on MPS and CUDA | AG3: PyTorch: Learn the Basics — https://docs.pytorch.org/tutorials/beginner/basics/intro.html RunPod docs — https://docs.runpod.io | AH3: prep/M00-start/E02-setup-uv-pytorch-mps-vs-cuda-runpod-in-10-minute.md | AI3: code/M00-start/e02_setup_uv_pytorch_mps_vs_cuda_runpod_in_10_minute.py | AJ3: explainers/scenes/m00e02_setup_uv_pytorch_mps_vs_cuda_run.py | AK3: M00E01
A4: 3 | B4: M01E01 | C4: M01 PyTorch from Zero | D4: 46311 | E4: Tensors: what they actually are | F4: A PyTorch tensor is not a grid of numbers. It is a flat list plus four pieces of metadata, and transpose copies nothing. | G4: 0:00 HOOK — A PyTorch tensor is not a grid of numbers. It is a flat list plus four pieces of metadata, and transpose copies nothing. 0:15 QUESTION — Every weight in Llama 3 and every KV cache entry in vLLM is a tensor. If you think of it as a grid you will be confused by views, contiguous, and why some reshapes fail. Think of it as memory plus a recipe for reading it. 0:45 INTUITION — Storage is one flat 1D block of bytes. Shape says how many steps along each axis. Stride says how many elements to jump in storage for one step along each axis. Dtype says how to read the bytes, device says where they live. [EXPLAINER plays here.] 1:45 MATH — Address rule: element x[i, j] lives at storage[offset + i * stride[0] + j * stride[1]]. For a contiguous (2, 3) tensor, stride is (3, 1). Transpose to (3, 2) swaps the strides to (1, 3). No bytes move. 2:30 CODE — x = torch.arange(6.).reshape(2, 3). Print x.shape, x.stride(), x.dtype, x.device, x.storage_offset(), x.data_ptr(). Print x.untyped_storage().nbytes(), 24, which is 6 float32 values. y = x.t(): y.stride() is (1, 3), y.data_ptr() == x.data_ptr() is True. Then build it by hand: flat = torch.tensor([0., 1., 2., 3., 4., 5.]); mine = torch.as_strided(flat, size=(2, 3), stride=(3, 1)). Then torch.as_strided(flat, (3, 2), (1, 3)) gives the transpose with no copy. 4:45 RECEIPT — torch.equal(torch.as_strided(flat, (2, 3), (3, 1)), x) and torch.equal(torch.as_strided(flat, (3, 2), (1, 3)), x.t()) both True. Write my_index(flat, offset, stride, i, j) using the address rule and assert it equals x[i, j] for every i, j. 5:30 MEASURE — x.element_size() is 4 bytes for float32, 2 for bfloat16. Write y[0, 1] = 100 and print x: x changed, proof they share storage. 6:15 TAKEAWAY — A tensor is storage plus shape, stride, offset, dtype, device. Interview line: transpose is free because it only swaps strides, the cost shows up later when a kernel needs contiguous memory. 6:40 NEXT — Now that we know what a tensor is, let's make a lot of them and pick the right number format. Next: Creating tensors and dtypes. | H4: addr(x[i_0, ..., i_k]) = offset + sum_d i_d * stride[d]; contiguous strides: stride[d] = prod_{e > d} shape[e]; transpose swaps stride[0] and stride[1]. | I4: Inspect x = torch.arange(6.).reshape(2, 3): shape (2, 3), stride (3, 1), storage_offset 0, untyped_storage().nbytes() 24. Rebuild it and its transpose (3, 2) with torch.as_strided(flat, size, stride). Write my_index(flat, offset, stride, i, j) implementing the address rule. | J4: assert torch.equal(torch.as_strided(flat, (2, 3), (3, 1)), x); assert torch.equal(torch.as_strided(flat, (3, 2), (1, 3)), x.t()); assert x.t().data_ptr() == x.data_ptr(); my_index matches x[i, j] for all 6 entries. | K4: x.storage() is deprecated (TypedStorage); use x.untyped_storage(); stride is counted in elements, but data_ptr and nbytes are in bytes; as_strided with a wrong stride happily reads overlapping or garbage memory without error. | L4: What is the difference between a tensor's shape and its stride? Shape is the logical size of each axis; stride is how many storage elements you skip to move one step along that axis. Views like transpose, slicing and expand change only shape, stride and offset, never the data. | M4: What looks like a two by three grid of numbers is really six numbers sitting in one flat row of memory. The shape tells us there are two rows and three columns. The stride tells us how far to jump in memory for each. To move down one row we jump three slots. To move right one column we jump one slot. That is stride three, one. Now transpose. The flat memory does not move at all. We only swap the strides to one, three, and read it differently. Any element's address is the offset plus each index times its stride. That single formula explains every view in PyTorch. Dtype says how many bytes each slot takes, four for float32, two for bfloat16. Device says which memory chip holds the row. | N4: The 2:30 CODE beat showing transpose has the same data_ptr and swapped strides. Caption: 'Transpose copies zero bytes. Here is proof.' | O4: Y | P4: N | Q4: N | R4: N | S4: N | T4: N | U4: N | V4: N | W4: N | X4: N | Z4: PyTorch Tensors Explained: storage, stride, and why transpose is free | AA4: TENSORS AREN'T GRIDS | AB4: A PyTorch tensor is a flat block of memory plus shape, stride, offset, dtype, device. Transpose swaps two strides and copies zero bytes. I rebuilt a tensor and its transpose by hand with torch.as_strided. Code + video: | AC4: Started the PyTorch from Zero series with what a tensor actually is: flat storage plus shape, stride, offset, dtype and device. I rebuilt a (2, 3) tensor and its transpose from a flat list using as_strided and showed both share one data pointer. The address formula offset + sum(i_d * stride_d) explains every view operation. | AD4: Mac | AE4: A tensor is storage + shape + stride + dtype + device | AF4: Inspect .storage(), .stride(), .data_ptr(); build a 2x3 tensor by hand from a flat list | AG4: PyTorch: Learn the Basics — https://docs.pytorch.org/tutorials/beginner/basics/intro.html PyTorch documentation — https://docs.pytorch.org/docs/stable/index.html | AH4: prep/M01-pytorch/E01-tensors-what-they-actually-are.md | AI4: code/M01-pytorch/e01_tensors_what_they_actually_are.py | AJ4: explainers/scenes/m01e01_tensors_what_they_actually_are.py | AK4: M00E02
A5: 4 | B5: M01E02 | C5: M01 PyTorch from Zero | D5: 46312 | E5: Creating tensors and dtypes | F5: In float16, 70000 is infinity. In bfloat16, 1 plus 0.001 is exactly 1. Every LLM trains in one of these. | G5: 0:00 HOOK — In float16, 70000 is infinity. In bfloat16, 1 plus 0.001 is exactly 1. Every LLM trains in one of these. 0:15 QUESTION — Llama 3 and DeepSeek-V3 train in bfloat16, and DeepSeek-V3 pushes matmuls down to FP8. Pick the wrong dtype and your loss goes to nan or your updates vanish. You need to know what each format can and cannot represent. 0:45 INTUITION — A float is sign, exponent, mantissa. Exponent bits buy range, mantissa bits buy precision. float32 is 8 and 23. float16 is 5 and 10. bfloat16 is 8 and 7: float32's range with very little precision. [EXPLAINER plays here.] 1:45 MATH — value = (-1)^s * 2^(e - bias) * (1.m). Machine epsilon = 2^-(mantissa bits): float32 2^-23 = 1.19e-7, float16 2^-10 = 9.8e-4, bfloat16 2^-7 = 7.8e-3. Max float16 = 65504. 2:30 CODE — Creation tour: torch.zeros(2, 3), torch.ones_like(x), torch.arange(0, 10, 2), torch.linspace(0, 1, 5), torch.randn(3, 4), torch.full((2, 2), 7.). Show torch.tensor([1, 2]).dtype is int64 and torch.tensor([1., 2.]).dtype is float32. Then for dt in (torch.float32, torch.float16, torch.bfloat16): print torch.finfo(dt).max, .eps, .tiny. 4:30 CODE — Overflow and swamping demos: torch.tensor(70000., dtype=torch.float16) prints inf. torch.tensor(70000., dtype=torch.bfloat16) prints 70144, finite but rounded. torch.tensor(1., dtype=torch.bfloat16) + 0.001 equals 1. Then 0.1 + 0.2 == 0.3 is False in Python and in float64; use torch.isclose. 5:45 RECEIPT — assert torch.finfo(torch.bfloat16).eps == 2**-7 and torch.finfo(torch.float16).max == 65504 and torch.isinf(torch.tensor(7e4, dtype=torch.float16)). Accumulation test: sum 10000 copies of 1e-4 in bfloat16 with a Python loop versus float32; float32 lands near 1.0, bfloat16 stalls far below it because small adds round away. 7:00 MEASURE — Show memory per parameter: 4, 2, 2, 1 bytes for fp32, fp16, bf16, fp8. An 8B model is 32 GB in fp32 and 16 GB in bf16, just for weights. 7:30 TAKEAWAY — bfloat16 keeps float32's range so it rarely overflows, but its 8 bits of precision mean you accumulate in float32. Interview line: mixed precision means low precision storage and matmul inputs, float32 accumulators and master weights. 8:00 NEXT — We can make tensors. Now we slice them, and learn when a slice is free and when it secretly copies. Next: Indexing, views and strides. | H5: value = (-1)^s * 2^(e - bias) * 1.m; eps = 2^-(mantissa bits): fp32 1.19e-7, fp16 9.77e-4, bf16 7.81e-3; fp16 max 65504; bf16 max ~3.39e38. | I5: A dtype tour script: creation functions (zeros, ones_like, arange, linspace, randn, full) with printed shapes and dtypes; a finfo table for float32/float16/bfloat16 (max, eps, tiny); overflow demo at 7e4; swamping demo 1 + 1e-3 in bf16; accumulate_sum(n=10000, val=1e-4, dtype) loop returning the running sum. | J5: assert torch.finfo(torch.bfloat16).eps == 2**-7; assert torch.finfo(torch.float16).max == 65504.0; assert torch.isinf(torch.tensor(7e4, dtype=torch.float16)); assert (torch.tensor(1., dtype=torch.bfloat16) + 1e-3).item() == 1.0; accumulate_sum in float32 within 1e-3 of 1.0 while bf16 is not. | K5: torch.tensor([1, 2]) is int64, so dividing works but in-place float ops on it raise a dtype error; torch.arange(0, 1, 0.1) can give a surprising length from float rounding, prefer linspace; float64 is not supported on MPS. | L5: Why do LLMs train in bfloat16 instead of float16? bfloat16 has the same 8 exponent bits as float32, so activations and gradients do not overflow and you usually need no loss scaling; float16 has more precision but a max of 65504, so it needs dynamic loss scaling to avoid inf and underflow. | M5: Every float is three fields packed into bits: a sign, an exponent that sets the scale, and a mantissa that sets the detail. Float32 spends eight bits on exponent and twenty three on mantissa. Huge range, about seven decimal digits of precision. Float16 cuts the exponent to five bits. Its largest number is 65504, so seventy thousand becomes infinity. Bfloat16 keeps all eight exponent bits and cuts the mantissa to seven. Float32's range, but only about two digits. Here is the cost. Add one thousandth to one in bfloat16 and the gap between representable numbers swallows it whole. So modern training stores tensors in bfloat16 for speed and memory, and adds them up in float32 so nothing gets lost. | N5: The 4:30 CODE overflow/swamping demo. Caption: 'In float16, 70,000 is infinity.' | O5: Y | P5: N | Q5: N | R5: N | S5: N | T5: N | U5: N | V5: N | W5: N | X5: N | Z5: PyTorch dtypes: float32 vs float16 vs bfloat16, and when they break | AA5: 70000 = INFINITY | AB5: float16 max is 65504, so 70000 becomes inf. bfloat16 never overflows like that, but 1 + 0.001 == 1 in bf16. That is why we store in bf16 and accumulate in fp32. Showed it all with torch.finfo. Code + video: | AC5: Episode 2 of PyTorch from Zero covers dtypes. I measured float32, float16 and bfloat16 with torch.finfo and reproduced the two classic failures: float16 overflow at 70000 and bfloat16 swamping where 1 + 0.001 rounds to 1. Summing 10,000 small values in bf16 stalls far below the true answer, which is exactly why mixed precision keeps float32 accumulators. | AD5: Mac | AE5: zeros/ones/arange/randn; float32 vs bfloat16 vs int64; why 0.1+0.2 bites | AF5: Show bf16 vs fp16 range/precision with torch.finfo; overflow demo | AG5: PyTorch documentation — https://docs.pytorch.org/docs/stable/index.html | AH5: prep/M01-pytorch/E02-creating-tensors-and-dtypes.md | AI5: code/M01-pytorch/e02_creating_tensors_and_dtypes.py | AJ5: explainers/scenes/m01e02_creating_tensors_and_dtypes.py | AK5: M01E01
A6: 5 | B6: M01E03 | C6: M01 PyTorch from Zero | D6: 46312 | E6: Indexing, views and strides | F6: x.t().view(6) crashes, x.t().reshape(6) works. The difference is a hidden memory copy you should know about. | G6: 0:00 HOOK — x.t().view(6) crashes, x.t().reshape(6) works. The difference is a hidden memory copy you should know about. 0:15 QUESTION — In a transformer we split heads with view and transpose on every forward pass of every layer. If one of those calls copies, you pay memory bandwidth for nothing. If you call view on the wrong tensor, it crashes mid training. 0:45 INTUITION — Basic slicing and transpose are views: same storage, new shape, stride, offset. A tensor is contiguous when its strides match the row-major layout. view needs to express the new shape with strides alone; reshape will copy if it can't. [EXPLAINER plays here.] 1:45 CODE — x = torch.arange(12.).reshape(3, 4). Slices: x[1] has offset 4, stride (1,). x[:, 1] has offset 1, stride (4,). x[::2] has stride (8, 1). All share x.data_ptr() base storage: check x[:, 1].untyped_storage().data_ptr() == x.untyped_storage().data_ptr(). Advanced indexing x[[0, 2]] is a copy: different storage pointer. 3:30 CODE — y = x.t(): y.is_contiguous() is False. y.view(12) raises RuntimeError about size and stride being incompatible. y.reshape(12) works and its storage pointer differs, so it copied. y.contiguous() copies once and then .view(12) works. x.contiguous() on an already contiguous tensor returns the same tensor, no copy. 4:45 CODE — The transformer pattern: q of shape (B, T, C) with C = H * D. q.view(B, T, H, D).transpose(1, 2) gives (B, H, T, D), a view. Merging heads back needs out.transpose(1, 2).contiguous().view(B, T, C), or out.transpose(1, 2).reshape(B, T, C). 5:45 RECEIPT — def shares_storage(a, b): return a.untyped_storage().data_ptr() == b.untyped_storage().data_ptr(). Assert shares_storage(x, x[:, 1]), shares_storage(x, x.t()), not shares_storage(x, x[[0, 2]]), not shares_storage(x, x.t().reshape(12)). And pytest.raises(RuntimeError) around x.t().view(12). 6:45 MEASURE — Time 100 calls of a (4096, 4096) .t() versus .t().contiguous() on MPS with sync: microseconds versus a real memory copy. That gap is the cost of a hidden copy. 7:15 TAKEAWAY — Views are free, copies are bandwidth. Interview line: view never copies and fails if strides can't express the shape, reshape returns a view when possible and silently copies otherwise. 7:40 NEXT — Views let tensors of different shapes share memory. Broadcasting lets them share math, and it is the source of the most silent bugs in PyTorch. Next: Broadcasting: the bug factory. | H6: contiguous iff stride[d] = prod_{e > d} shape[e] for all d; slice x[a:b:s] along dim d: offset += a * stride[d], stride[d] *= s. | I6: On x = torch.arange(12.).reshape(3, 4): print shape/stride/storage_offset for x[1], x[:, 1], x[::2], x.t(), x[[0, 2]]; shares_storage(a, b) helper; view vs reshape vs contiguous on the transpose; the head split q (B, T, C) -> (B, H, T, D) and merge back with B=2, T=5, H=4, D=8. | J6: assert shares_storage(x, x[:, 1]) and shares_storage(x, x.t()); assert not shares_storage(x, x[[0, 2]]); assert not shares_storage(x, x.t().reshape(12)); with pytest.raises(RuntimeError): x.t().view(12); torch.equal(merged, q) after split and merge. | K6: Comparing x.data_ptr() of a slice to the base fails because data_ptr includes the offset, compare untyped_storage().data_ptr() instead; in-place writes through a view mutate the original tensor; advanced (list or boolean) indexing always copies, while basic slicing never does. | L6: When does reshape copy? When the requested shape cannot be expressed as a new set of strides over the existing storage, typically after transpose or permute; then it calls contiguous internally. view raises an error in that case instead. | M6: Here is a three by four tensor and the twelve numbers of storage underneath. Every view we take keeps pointing at this row. Take column one. Same storage, offset one, stride four. Nothing is copied, we just read every fourth slot. Transpose swaps the strides. The tensor is now non contiguous, meaning reading it row by row jumps around in memory. Ask view to flatten it to twelve and PyTorch refuses. No single stride can walk this order through the flat storage. Reshape quietly copies the data into a fresh, ordered block, then flattens that. It worked, but we paid for a copy. In attention we split heads with view and transpose for free, then pay one contiguous copy when we merge them back. | N6: The 3:30 CODE beat: view crashes, reshape works, storage pointers prove the copy. Caption: 'reshape is secretly copying your tensor.' | O6: Y | P6: N | Q6: N | R6: N | S6: N | T6: N | U6: N | V6: N | W6: N | X6: N | Z6: PyTorch view vs reshape vs contiguous: when tensors secretly copy | AA6: VIEW CRASHES. WHY? | AB6: x.t().view(6) raises, x.t().reshape(6) works. reshape silently copied because no stride can express that order. Proved every view vs copy with storage pointers, including the attention head split. Code + video: | AC6: In this episode I proved which PyTorch indexing operations are views and which copy, by comparing storage pointers. Slicing and transpose are free, advanced indexing and reshape-after-transpose copy. On a 4096x4096 tensor, the difference between .t() and .t().contiguous() is the difference between metadata and a full memory pass. | AD6: Mac | AE6: Slicing returns views; transpose changes strides; when .contiguous() copies | AF6: Prove view vs copy with data_ptr; reshape vs view failure case | AG6: PyTorch documentation — https://docs.pytorch.org/docs/stable/index.html | AH6: prep/M01-pytorch/E03-indexing-views-and-strides.md | AI6: code/M01-pytorch/e03_indexing_views_and_strides.py | AJ6: explainers/scenes/m01e03_indexing_views_and_strides.py | AK6: M01E01
A7: 6 | B7: M01E04 | C7: M01 PyTorch from Zero | D7: 46314 | E7: Broadcasting: the bug factory | F7: Subtract a shape (N,) tensor from a shape (N, 1) tensor and PyTorch gives you an N by N matrix. No error. | G7: 0:00 HOOK — Subtract a shape (N,) tensor from a shape (N, 1) tensor and PyTorch gives you an N by N matrix. No error. 0:15 QUESTION — Broadcasting is how GPT-2 adds a (T, C) position embedding to a (B, T, C) batch, and how a causal mask hits every head at once. It is also how a regression loss silently trains on N squared wrong pairs. 0:45 INTUITION — Rule 1: line up shapes from the right; missing dims count as 1. Rule 2: each pair of dims must be equal or one of them must be 1, and the 1 gets stretched with stride 0. [EXPLAINER plays here.] 1:45 MATH — Pairwise squared distance: D[i, j] = ||x_i - y_j||^2 with x (N, D), y (M, D). Broadcast x[:, None, :] (N, 1, D) minus y[None, :, :] (1, M, D) gives (N, M, D), sum over the last dim gives (N, M). Memory cost N * M * D, which is why the expanded form ||x||^2 + ||y||^2 - 2 x y^T exists. 2:45 CODE — def pairwise_dist(x, y): diff = x[:, None, :] - y[None, :, :]; return diff.pow(2).sum(-1).sqrt(). Shapes printed at every line: (N, 1, D), (1, M, D), (N, M, D), (N, M). Show y.expand(4, 3, 8).stride() has a 0, so the stretch costs no memory until the subtraction materializes it. 4:15 CODE — The bug: pred = model(x) with shape (N, 1), target with shape (N,). loss = ((pred - target) ** 2).mean(). Print (pred - target).shape: (N, N). It trains, it just trains on garbage. F.mse_loss(pred, target) at least emits a UserWarning about different sizes. Fix: target.unsqueeze(1) or pred.squeeze(-1), plus assert pred.shape == target.shape. 5:30 RECEIPT — torch.testing.assert_close(pairwise_dist(x, y), torch.cdist(x, y)) for x (128, 16), y (64, 16). And the bug check: buggy loss != correct loss, and correct loss equals F.mse_loss(pred.squeeze(-1), target). 6:30 MEASURE — Fit y = 3x on 100 points with the buggy loss and the correct loss. The buggy one converges to a weight near 0 instead of 3, because it fits every pred against the mean of all targets. Plot both. 7:15 TAKEAWAY — Align from the right, 1s stretch, everything else must match. Interview line: I put shape asserts on every loss input, because broadcasting turns a shape bug into a wrong number instead of an error. 7:40 NEXT — Broadcasting handles elementwise math. The real work in a transformer is matmuls and reductions. Next: Matmul, reductions and einsum. | H7: Broadcast: align shapes right, dims equal or one is 1, result dim = max; D[i, j] = sqrt(sum_k (x_ik - y_jk)^2); ||x - y||^2 = ||x||^2 + ||y||^2 - 2 x . y. | I7: pairwise_dist(x (N, D), y (M, D)) -> (N, M) via x[:, None, :] - y[None, :, :]; demo expand stride 0; reproduce (N, 1) - (N,) -> (N, N) bug in a 1-parameter linear regression fit and fix it. | J7: torch.testing.assert_close(pairwise_dist(x, y), torch.cdist(x, y)) for x (128, 16), y (64, 16); assert (pred - target).shape == (N, N) for the bug and (pred.squeeze(-1) - target).shape == (N,) for the fix. | K7: (N, 1) minus (N,) broadcasts to (N, N) with no error; keepdim=False reductions drop a dim and then broadcast against the wrong axis; torch.cdist on float32 may use a matmul-based path for large inputs, so compare with a tolerance, not torch.equal. | L7: What are PyTorch's broadcasting rules? Compare shapes from the trailing dimension; each pair must be equal or one must be 1 (or absent), and size-1 dims are virtually expanded with stride 0. The classic bug is (N, 1) vs (N,) producing (N, N). | M7: Broadcasting starts by lining two shapes up from the right, like adding numbers by their last digit. Here is a four by three tensor plus a length three vector. The missing leading dimension counts as one. A dimension of one gets stretched to match, by setting its stride to zero. The same row is read four times, no copying. Now the trap. A column of N predictions minus a row of N targets. Both stretch, and we get an N by N grid. The loss averages all of those pairs, every prediction against every target, and it still returns one clean number. The fix is one character of shape. Make both tensors N by one, or both length N, and assert it before the loss. | N7: The 4:15 CODE bug: print (pred - target).shape and get (100, 100). Caption: 'This PyTorch bug trains fine. And learns nothing.' | O7: Y | P7: N | Q7: N | R7: N | S7: N | T7: N | U7: N | V7: N | W7: N | X7: N | Z7: PyTorch Broadcasting: 2 rules and the silent (N,1) vs (N,) bug | AA7: (N,1) - (N,) = BUG | AB7: pred is (N, 1), target is (N,). pred - target is (N, N). No error, the loss trains, the weight converges to the wrong value. Two broadcasting rules, one pairwise distance that matches torch.cdist, and the fix. Code + video: | AC7: Broadcasting episode: I implemented a pairwise distance matrix with pure broadcasting and matched torch.cdist, then reproduced the classic (N, 1) vs (N,) bug. A linear fit with the buggy loss converges to the wrong weight with no error at all. The fix is a one-line shape assert on every loss input. | AD7: Mac | AE7: The 2 broadcasting rules, and the silent (N,) vs (N,1) bug | AF7: Pairwise distance matrix with broadcasting; reproduce and fix the (N,)+(N,1) bug | AG7: PyTorch documentation — https://docs.pytorch.org/docs/stable/index.html | AH7: prep/M01-pytorch/E04-broadcasting-the-bug-factory.md | AI7: code/M01-pytorch/e04_broadcasting_the_bug_factory.py | AJ7: explainers/scenes/m01e04_broadcasting_the_bug_factory.py | AK7: M01E03
A8: 7 | B8: M01E05 | C8: M01 PyTorch from Zero | D8: 46314 | E8: Matmul, reductions and einsum | F8: Attention scores in one line, written three ways: bmm, einsum, einops. Same numbers, very different readability. | G8: 0:00 HOOK — Attention scores in one line, written three ways: bmm, einsum, einops. Same numbers, very different readability. 0:15 QUESTION — Over 90 percent of a transformer's FLOPs are matmuls. Llama code is full of transposes and dim arguments that are easy to get wrong by one axis. We want matmuls whose shapes document themselves. 0:45 INTUITION — * is elementwise. @ is matrix multiply and broadcasts batch dims. torch.mm is strictly 2D, torch.bmm strictly 3D batched. A reduction collapses one dim; the dim argument names which one disappears. einsum names every axis with a letter. [EXPLAINER plays here.] 1:45 MATH — Scores S[b, t, s] = sum_d Q[b, t, d] K[b, s, d]. In matrix form S = Q K^T per batch, shapes (B, T, D) @ (B, D, S) -> (B, T, S). The summed index d appears in the inputs but not the output: that is the einsum rule. 2:30 CODE — Reductions first: x = torch.randn(4, 5). x.sum(dim=0).shape is (5,), x.sum(dim=1, keepdim=True).shape is (4, 1), x.max(dim=-1) returns values and indices, x.mean(-1). Then matmul family: A @ B for (2, 3) @ (3, 4); torch.mm same; torch.bmm on (8, 2, 3) and (8, 3, 4); @ with (8, 2, 3) and a plain (3, 4) broadcasts; bmm refuses. 4:15 CODE — q, k = torch.randn(2, 5, 16), torch.randn(2, 7, 16). s1 = torch.bmm(q, k.transpose(1, 2)). s2 = torch.einsum('btd,bsd->bts', q, k). s3 = einops.einsum(q, k, 'b t d, b s d -> b t s'). Bonus: einops.rearrange(x, 'b t (h d) -> b h t d', h=4) replaces the view plus transpose from the views episode. 5:45 RECEIPT — torch.testing.assert_close(s1, s2); torch.testing.assert_close(s1, s3); and assert_close(s1, q @ k.transpose(-2, -1)). All shapes (2, 5, 7). rearrange result equals q.view(B, T, H, D).transpose(1, 2). 6:45 MEASURE — Time s1, s2, s3 at B=32, T=1024, D=64 on MPS with sync: they dispatch to the same batched matmul, so times are within noise. einsum is documentation, not a slowdown. 7:15 TAKEAWAY — Name your axes and the shapes check themselves. Interview line: for a matmul of (M, K) by (K, N) the FLOPs are 2 M N K, and the contracted index is the one missing from the output. 7:40 NEXT — We can compute anything forward. Now PyTorch's real trick, computing gradients of all of it automatically. Next: Autograd: how PyTorch computes gradients. | H8: S[b,t,s] = sum_d Q[b,t,d] K[b,s,d] (S = Q K^T); FLOPs(M x K @ K x N) = 2 M N K; reduction over dim d removes that axis unless keepdim=True. | I8: Reductions demo on (4, 5); matmul family demo (@, mm, bmm, broadcasting @); scores3(q (B, T, D), k (B, S, D)) -> three (B, T, S) results via torch.bmm, torch.einsum('btd,bsd->bts'), einops.einsum; einops.rearrange head split 'b t (h d) -> b h t d'. | J8: torch.testing.assert_close(torch.bmm(q, k.transpose(1, 2)), torch.einsum('btd,bsd->bts', q, k)); torch.testing.assert_close(torch.bmm(q, k.transpose(1, 2)), einops.einsum(q, k, 'b t d, b s d -> b t s')); torch.equal(rearrange(x, 'b t (h d) -> b h t d', h=4), x.view(B, T, 4, D).transpose(1, 2)). | K8: torch.bmm requires both inputs to be exactly 3D with equal batch size, no broadcasting; transpose(1, 2) vs transpose(-2, -1) differ once you add a head dim; x.max(dim=...) returns a (values, indices) named tuple, not a tensor. | L8: What's the FLOP count of computing attention scores QK^T for batch B, heads H, sequence T, head dim D? 2 * B * H * T * T * D, quadratic in T, and the same again for multiplying the probabilities by V. | M8: Elementwise times multiplies matching cells. Matrix multiply is different: each output cell is a whole row meeting a whole column. For attention scores, each query row meets each key row. The shared axis d is summed away and vanishes from the result. With bmm we have to transpose the keys ourselves so the shapes line up, and the shape logic lives in our head. With einsum we write the letters b, t, d and b, s, d, then b, t, s. The missing letter d is the one summed. Einops says the same thing with readable names and spaces, and rearrange does head splitting with no view or transpose. All three dispatch to the same batched matrix multiply, so we get the documentation for free, with no speed cost. | N8: The 4:15 CODE beat: the same attention scores in bmm, einsum and einops, all assert_close. Caption: 'Write attention scores 3 ways. Which one would you read?' | O8: Y | P8: N | Q8: N | R8: N | S8: N | T8: N | U8: N | V8: N | W8: N | X8: N | Z8: PyTorch matmul vs bmm vs einsum vs einops: attention scores 3 ways | AA8: ONE MATMUL, 3 WAYS | AB8: Attention scores QK^T written with torch.bmm, torch.einsum and einops.einsum. All assert_close, all within noise on time. The summed index is the letter missing from the output. Code + video: | AC8: This episode covered matmul and reductions in PyTorch: @ vs mm vs bmm, the dim argument, and einsum. I computed batched attention scores with bmm, einsum and einops, verified they match, and timed them on the M4 GPU: identical speed, because they hit the same kernel. einsum is free documentation for shapes. | AD8: Mac | AE8: @ vs * vs mm vs bmm; the dim argument; einsum/einops as shape documentation | AF8: Batched attention scores 3 ways (bmm, einsum, einops) all allclose | AG8: PyTorch documentation — https://docs.pytorch.org/docs/stable/index.html einops — https://einops.rocks | AH8: prep/M01-pytorch/E05-matmul-reductions-and-einsum.md | AI8: code/M01-pytorch/e05_matmul_reductions_and_einsum.py | AJ8: explainers/scenes/m01e05_matmul_reductions_and_einsum.py | AK8: M01E04
